Workbook

Sheet Transaction
A1: Emp Code | B1: Employee Name | C1: Date Of Joining | D1: Date Of Leaving | E1: Level | F1: Department | G1: Employment_Type | H1: Status | I1: Status Reason | J1: Location | K1: Date Of Confirmation | L1: Prior Experience | M1: Current Company Experience | N1: Total Experience | O1: Project Name | P1: Date Of Birth | Q1: Gender | R1: Reason Category | S1: Reason for Resignation | T1: Attrition | U1: Source | V1: Age | W1: Blood Group | X1: Marital Status | Y1: Address | Z1: Phone No | AA1: Rating | AB1: Education | AC1: region | AD1: Skills
A2: E7 | B2: GAYLE NEWENHAM | C2: 42725 | E2: L8 | F2: BI | G2: Employees | H2: Active | I2: Confirmed | J2: Gurugram | K2: 40408 | L2: 10 | M2: =IF(H2<>"03 Exit",(TODAY()-C2)/365,DATEDIF(C2,D2,"Y")) -> 6.7808219 | N2: =L2+M2 -> 16.780822 | O2: DHFL | P2: 27432 | Q2: Male | T2: =IF(D2="","No","Yes") -> No | U2: Referrals | V2: 44 | W2: AB+ | X2: Married | Y2: Address | Z2: 1539228581 | AA2: 3 | AB2: Master's | AC2: region_15 | AD2: Control Assessment
A3: E12 | B3: CHRISTIAN MCWHIRTER | C3: 42726 | E3: L8 | F3: BI | G3: Employees | H3: Active | I3: Confirmed | J3: Gurugram | K3: 40408 | L3: 10 | M3: =IF(H3<>"03 Exit",(TODAY()-C3)/365,DATEDIF(C3,D3,"Y")) -> 6.7780822 | N3: =L3+M3 -> 16.778082 | O3: UST India | P3: 31393 | Q3: Male | T3: =IF(D3="","No","Yes") -> No | U3: Social media | V3: 37 | W3: B+ | X3: Married | Y3: Address | Z3: 4049812195 | AA3: 4 | AB3: Master's | AC3: region_2 | AD3: Control Assessment
A4: E14 | B4: CORY BLISSETT | C4: 42727 | E4: L8 | F4: BI | G4: Employees | H4: Active | I4: Confirmed | J4: Pune | K4: 40408 | L4: 10 | M4: =IF(H4<>"03 Exit",(TODAY()-C4)/365,DATEDIF(C4,D4,"Y")) -> 6.7753425 | N4: =L4+M4 -> 16.775342 | O4: Adobe | P4: 31815 | Q4: Male | T4: =IF(D4="","No","Yes") -> No | U4: Career Fairs | V4: 22 | W4: B- | X4: Unmarried | Y4: Address | Z4: 4325856210 | AA4: 3 | AB4: MBA | AC4: region_15 | AD4: Control Assessment
A5: E15 | B5: BRETT DIERCKS | C5: 42728 | E5: L8 | F5: BI | G5: Employees | H5: Active | I5: Confirmed | J5: Pune | K5: 40408 | L5: 10 | M5: =IF(H5<>"03 Exit",(TODAY()-C5)/365,DATEDIF(C5,D5,"Y")) -> 6.7726027 | N5: =L5+M5 -> 16.772603 | O5: DHFL | P5: 26888 | Q5: Male | T5: =IF(D5="","No","Yes") -> No | U5: job boards | V5: 26 | W5: B+ | X5: Unmarried | Y5: Address | Z5: 1855805439 | AA5: 3 | AB5: Master's | AC5: region_13 | AD5: Control Assessment
A6: E24 | B6: JACOB DETERS | C6: 42767 | E6: L5 | F6: BI | G6: Employees | H6: Active | I6: Confirmed | J6: Pune | K6: 40510 | L6: 0 | M6: =IF(H6<>"03 Exit",(TODAY()-C6)/365,DATEDIF(C6,D6,"Y")) -> 6.6657534 | N6: =L6+M6 -> 6.6657534 | O6: UST India | P6: 32285 | Q6: Male | T6: =IF(D6="","No","Yes") -> No | U6: Referrals | V6: 26 | W6: AB- | X6: Unmarried | Y6: Address | Z6: 1607018686 | AA6: 3 | AB6: MBA | AC6: region_15 | AD6: VAPT
A7: E27 | B7: KELLEY CLAUSING | C7: 40406 | E7: L8 | F7: BI | G7: Employees | H7: Active | I7: Confirmed | J7: Pune | K7: 40496 | L7: 10 | M7: =IF(H7<>"03 Exit",(TODAY()-C7)/365,DATEDIF(C7,D7,"Y")) -> 13.134247 | N7: =L7+M7 -> 23.134247 | O7: DHFL | P7: 30372 | Q7: Male | T7: =IF(D7="","No","Yes") -> No | U7: Referrals | V7: 37 | W7: AB+ | X7: Married | Y7: Address | Z7: 2904261610 | AA7: 3 | AB7: MBA | AC7: region_15 | AD7: Control Assessment
A8: E36 | B8: LISA BARRY | C8: 40742 | E8: L4 | F8: Cloud | G8: Employees | H8: Active | I8: Confirmed | J8: Gurugram | K8: 40922 | L8: 0 | M8: =IF(H8<>"03 Exit",(TODAY()-C8)/365,DATEDIF(C8,D8,"Y")) -> 12.213699 | N8: =L8+M8 -> 12.213699 | O8: Reliance | P8: 31718 | Q8: Male | T8: =IF(D8="","No","Yes") -> No | U8: Referrals | V8: 41 | W8: B- | X8: Married | Y8: Address | Z8: 3856685469 | AA8: 4 | AB8: Bachelor's | AC8: region_15 | AD8: .net Developer / C Sharp
A9: E38 | B9: RANDALL SKALICKY | C9: 40777 | E9: L5 | F9: BI | G9: Employees | H9: Active | I9: Confirmed | J9: Pune | K9: 40957 | L9: 2 | M9: =IF(H9<>"03 Exit",(TODAY()-C9)/365,DATEDIF(C9,D9,"Y")) -> 12.117808 | N9: =L9+M9 -> 14.117808 | O9: UST India | P9: 32080 | Q9: Male | T9: =IF(D9="","No","Yes") -> No | U9: Referrals | V9: 33 | W9: A- | X9: Married | Y9: Address | Z9: 1080440734 | AA9: 4 | AB9: MBA | AC9: region_22 | AD9: VAPT
A10: E53 | B10: REGINALD GUYTON | C10: 41180 | E10: L4 | F10: BI | G10: Employees | H10: Active | I10: Confirmed | J10: Pune | K10: 41360 | L10: 10 | M10: =IF(H10<>"03 Exit",(TODAY()-C10)/365,DATEDIF(C10,D10,"Y")) -> 11.013699 | N10: =L10+M10 -> 21.013699 | O10: Eureka Forbes | P10: 24685 | Q10: Male | T10: =IF(D10="","No","Yes") -> No | U10: Referrals | V10: 36 | W10: AB+ | X10: Unmarried | Y10: Address | Z10: 2757754001 | AA10: 4 | AB10: Bachelor's | AC10: region_2 | AD10: TPA
A11: E56 | B11: TED KEYLON | C11: 41302 | E11: L4 | F11: BI | G11: Employees | H11: Active | I11: Confirmed | J11: Pune | K11: 41395 | L11: 0 | M11: =IF(H11<>"03 Exit",(TODAY()-C11)/365,DATEDIF(C11,D11,"Y")) -> 10.679452 | N11: =L11+M11 -> 10.679452 | P11: 33318 | Q11: Male | T11: =IF(D11="","No","Yes") -> No | U11: Referrals | V11: 38 | W11: AB- | X11: Unmarried | Y11: Address | Z11: 7150875917 | AA11: 3 | AB11: MBA | AC11: region_13 | AD11: TPA
A12: E62 | B12: THOMAS WHALEN | C12: 41365 | E12: L4 | F12: BI | G12: Employees | H12: Active | I12: Confirmed | J12: Pune | K12: 41487 | L12: 0 | M12: =IF(H12<>"03 Exit",(TODAY()-C12)/365,DATEDIF(C12,D12,"Y")) -> 10.506849 | N12: =L12+M12 -> 10.506849 | O12: UST India | P12: 32670 | Q12: Female | T12: =IF(D12="","No","Yes") -> No | U12: Referrals | V12: 28 | W12: A+ | X12: Unmarried | Y12: Address | Z12: 5894904547 | AA12: 3 | AB12: Bachelor's | AC12: region_15 | AD12: TPA
A13: E63 | B13: ZAXXSON NATION | C13: 41365 | E13: L5 | F13: BI | G13: Employees | H13: Active | I13: Confirmed | J13: Pune | K13: 41487 | L13: 3.4 | M13: =IF(H13<>"03 Exit",(TODAY()-C13)/365,DATEDIF(C13,D13,"Y")) -> 10.506849 | N13: =L13+M13 -> 13.906849 | O13: EFL | P13: 31565 | Q13: Male | T13: =IF(D13="","No","Yes") -> No | U13: Referrals | V13: 36 | W13: AB- | X13: Married | Y13: Address | Z13: 3597082916 | AA13: 3 | AB13: MBA | AC13: region_22 | AD13: VAPT
A14: E64 | B14: ABIGAIL CLINE | C14: 41372 | E14: L4 | F14: BI | G14: Employees | H14: Active | I14: Confirmed | J14: Mumbai | K14: 41487 | L14: 3.5 | M14: =IF(H14<>"03 Exit",(TODAY()-C14)/365,DATEDIF(C14,D14,"Y")) -> 10.487671 | N14: =L14+M14 -> 13.987671 | O14: UST India | P14: 30519 | Q14: Male | T14: =IF(D14="","No","Yes") -> No | U14: Referrals | V14: 26 | W14: B- | X14: Unmarried | Y14: Address | Z14: 7723611545 | AA14: 3 | AB14: Master's | AC14: region_22 | AD14: TPA
A15: E76 | B15: ADAM CURRAN | C15: 41507 | E15: L6 | F15: BI | G15: Employees | H15: Active | I15: Confirmed | J15: Mumbai | K15: 41597 | L15: 12 | M15: =IF(H15<>"03 Exit",(TODAY()-C15)/365,DATEDIF(C15,D15,"Y")) -> 10.117808 | N15: =L15+M15 -> 22.117808 | O15: DHFL | P15: 29411 | Q15: Male | T15: =IF(D15="","No","Yes") -> No | U15: Referrals | V15: 36 | W15: AB+ | X15: Unmarried | Y15: Address | Z15: 2447602721 | AA15: 3 | AB15: Bachelor's | AC15: region_2 | AD15: VAPT
A16: E85 | B16: MALIK WHEATLEY | C16: 41813 | D16: 44335 | E16: L2 | F16: BI | G16: Employees | H16: 03 Exit | J16: PUNE | M16: =IF(H16<>"03 Exit",(TODAY()-C16)/365,DATEDIF(C16,D16,"Y")) -> 6 | Q16: Female | R16: Voluntary | S16: Family Reasons | T16: =IF(D16="","No","Yes") -> Yes | U16: Social media | V16: 28 | W16: A- | X16: Unmarried | Y16: Address | Z16: 9562177743 | AA16: 3 | AB16: MBA | AC16: region_15 | AD16: Python Engineer, Data science and ETL
A17: E89 | B17: ALAN LOWE | C17: 41834 | E17: L4 | F17: BI | G17: Employees | H17: Active | I17: Confirmed | J17: Pune | K17: 41927 | L17: 4 | M17: =IF(H17<>"03 Exit",(TODAY()-C17)/365,DATEDIF(C17,D17,"Y")) -> 9.2219178 | N17: =L17+M17 -> 13.221918 | O17: Eureka Forbes | P17: 32074 | Q17: Female | T17: =IF(D17="","No","Yes") -> No | U17: Referrals | V17: 48 | W17: O+ | X17: Unmarried | Y17: Address | Z17: 5053084886 | AA17: 3 | AB17: Master's | AC17: region_15 | AD17: TPA
A18: E98 | B18: AMANDA HELM | C18: 41911 | E18: L4 | F18: BI | G18: Employees | H18: Active | I18: Confirmed | J18: Pune | K18: 41944 | L18: 0.7 | M18: =IF(H18<>"03 Exit",(TODAY()-C18)/365,DATEDIF(C18,D18,"Y")) -> 9.0109589 | N18: =L18+M18 -> 9.7109589 | O18: UST India | P18: 33069 | Q18: Male | T18: =IF(D18="","No","Yes") -> No | U18: Referrals | V18: 36 | W18: B- | X18: Unmarried | Y18: Address | Z18: 7568347648 | AA18: 3 | AB18: MBA | AC18: region_15 | AD18: TPA
A19: E99 | B19: ANGELA BLACKMAN | C19: 41913 | E19: L5 | F19: BI | G19: On Contract | H19: Active | I19: Confirmed | J19: Gurugram | K19: =C19+89 -> 42002 | L19: 14 | M19: =IF(H19<>"03 Exit",(TODAY()-C19)/365,DATEDIF(C19,D19,"Y")) -> 9.0054795 | N19: =L19+M19 -> 23.005479 | O19: UST India | P19: 27729 | Q19: Male | T19: =IF(D19="","No","Yes") -> No | U19: Referrals | V19: 30 | W19: A+ | X19: Married | Y19: Address | Z19: 2993619626 | AA19: 3 | AB19: Master's | AC19: region_2 | AD19: VAPT
A20: E100 | B20: ARTHUR CAREY | C20: 42691 | E20: L6 | F20: BI | G20: Employees | H20: Active | I20: Confirmed | J20: Pune | K20: 42051 | L20: 20 | M20: =IF(H20<>"03 Exit",(TODAY()-C20)/365,DATEDIF(C20,D20,"Y")) -> 6.8739726 | N20: =L20+M20 -> 26.873973 | O20: DHFL | P20: 26138 | Q20: Male | T20: =IF(D20="","No","Yes") -> No | U20: Referrals | V20: 48 | W20: O- | X20: Unmarried | Y20: Address | Z20: 3398419796 | AA20: 3 | AB20: MBA | AC20: region_2 | AD20: VAPT
A21: E115 | B21: BONNIE PARR | C21: 42135 | E21: L4 | F21: Support | G21: Employees | H21: Active | I21: Confirmed | J21: Pune | K21: 42217 | L21: 7 | M21: =IF(H21<>"03 Exit",(TODAY()-C21)/365,DATEDIF(C21,D21,"Y")) -> 8.3972603 | N21: =L21+M21 -> 15.39726 | P21: 30817 | Q21: Male | T21: =IF(D21="","No","Yes") -> No | U21: Referrals | V21: 38 | W21: A+ | X21: Unmarried | Y21: Address | Z21: 3605137329 | AA21: 3 | AB21: Master's | AC21: region_15 | AD21: TPA
A22: E116 | B22: BRITTA BRACKNEY | C22: 42149 | E22: L4 | F22: BI | G22: Employees | H22: Active | I22: Confirmed | J22: Pune | K22: 42248 | L22: 0 | M22: =IF(H22<>"03 Exit",(TODAY()-C22)/365,DATEDIF(C22,D22,"Y")) -> 8.3589041 | N22: =L22+M22 -> 8.3589041 | O22: Cigna | P22: 33449 | Q22: Male | T22: =IF(D22="","No","Yes") -> No | U22: Referrals | V22: 35 | W22: A+ | X22: Unmarried | Y22: Address | Z22: 4034138457 | AA22: 3 | AB22: Bachelor's | AC22: region_15 | AD22: TPA
A23: E127 | B23: CARLA SMITH | C23: 42219 | E23: L5 | F23: BI | G23: Employees | H23: Active | I23: Confirmed | J23: Pune | K23: 42309 | L23: 13 | M23: =IF(H23<>"03 Exit",(TODAY()-C23)/365,DATEDIF(C23,D23,"Y")) -> 8.1671233 | N23: =L23+M23 -> 21.167123 | O23: OTIS | P23: 28766 | Q23: Male | T23: =IF(D23="","No","Yes") -> No | U23: Referrals | V23: 22 | W23: AB+ | X23: Unmarried | Y23: Address | Z23: 9557167069 | AA23: 4 | AB23: MBA | AC23: region_15 | AD23: VAPT
A24: E131 | B24: CHAD BETTIS | C24: 42226 | E24: L4 | F24: BI | G24: Employees | H24: Active | I24: Confirmed | J24: Gurugram | K24: 42318 | L24: 7 | M24: =IF(H24<>"03 Exit",(TODAY()-C24)/365,DATEDIF(C24,D24,"Y")) -> 8.1479452 | N24: =L24+M24 -> 15.147945 | O24: Adobe | P24: 30772 | Q24: Male | T24: =IF(D24="","No","Yes") -> No | U24: Referrals | V24: 36 | W24: O+ | X24: Unmarried | Y24: Address | Z24: 5473777717 | AA24: 3 | AB24: Bachelor's | AC24: region_13 | AD24: TPA
A25: E135 | B25: JILL BRUINGTON | C25: 42240 | E25: L4 | F25: QA & QC | G25: Employees | H25: Active | I25: Confirmed | J25: Pune | K25: 42339 | L25: 4.5 | M25: =IF(H25<>"03 Exit",(TODAY()-C25)/365,DATEDIF(C25,D25,"Y")) -> 8.109589 | N25: =L25+M25 -> 12.609589 | O25: IT | P25: 30281 | Q25: Female | T25: =IF(D25="","No","Yes") -> No | U25: Referrals | V25: 40 | W25: AB+ | X25: Married | Y25: Address | Z25: 7744269401 | AA25: 3 | AB25: Bachelor's | AC25: region_7 | AD25: ITGC
A26: E138 | B26: CHRISTOPHER SCHNELL | C26: 42263 | E26: L5 | F26: BI | G26: Employees | H26: Active | I26: Confirmed | J26: Gurugram | K26: 42262 | L26: 7 | M26: =IF(H26<>"03 Exit",(TODAY()-C26)/365,DATEDIF(C26,D26,"Y")) -> 8.0465753 | N26: =L26+M26 -> 15.046575 | O26: IT | P26: 31145 | Q26: Male | T26: =IF(D26="","No","Yes") -> No | U26: Referrals | V26: 44 | W26: AB- | X26: Unmarried | Y26: Address | Z26: 3553282486 | AA26: 3 | AB26: Master's | AC26: region_13 | AD26: IAM - Multiple Product
A27: E141 | B27: JORDAN JACKSON | C27: 42282 | D27: 44316 | E27: L3 | F27: BI | G27: Employees | H27: 03 Exit | J27: Pune | M27: =IF(H27<>"03 Exit",(TODAY()-C27)/365,DATEDIF(C27,D27,"Y")) -> 5 | Q27: Female | R27: Voluntary | S27: Growth Opportunities | T27: =IF(D27="","No","Yes") -> Yes | U27: Social media | V27: 33 | W27: A+ | X27: Married | Y27: Address | Z27: 3536341879 | AA27: 3 | AB27: Master's | AC27: region_7 | AD27: Python Engineer, Data science and ETL
A28: E145 | B28: CHRISTOPHER WILLS | C28: 42282 | E28: L3 | F28: BI | G28: Employees | H28: Active | I28: Confirmed | J28: Pune | K28: 42374 | L28: 0 | M28: =IF(H28<>"03 Exit",(TODAY()-C28)/365,DATEDIF(C28,D28,"Y")) -> 7.9945205 | N28: =L28+M28 -> 7.9945205 | O28: IT | P28: 33833 | Q28: Male | T28: =IF(D28="","No","Yes") -> No | U28: Referrals | V28: 28 | W28: A- | X28: Unmarried | Y28: Address | Z28: 6953753869 | AA28: 4 | AB28: Master's | AC28: region_7 | AD28: Python Engineer, Data science and ETL
A29: E150 | B29: CLARA THORPE | C29: 42324 | E29: L3 | F29: QA & QC | G29: Employees | H29: Active | I29: Confirmed | J29: Pune | K29: 42416 | L29: 2.11 | M29: =IF(H29<>"03 Exit",(TODAY()-C29)/365,DATEDIF(C29,D29,"Y")) -> 7.8794521 | N29: =L29+M29 -> 9.9894521 | O29: IT | P29: 31274 | Q29: Male | T29: =IF(D29="","No","Yes") -> No | U29: Referrals | V29: 39 | W29: B- | X29: Unmarried | Y29: Address | Z29: 9576493121 | AA29: 3 | AB29: Bachelor's | AC29: region_7 | AD29: SAP Controls Transformation
A30: E156 | B30: COLBY MARS | C30: 42370 | E30: L1 | F30: Support | G30: Employees | H30: Active | I30: Confirmed | J30: Pune | K30: 42461 | L30: 2 | M30: =IF(H30<>"03 Exit",(TODAY()-C30)/365,DATEDIF(C30,D30,"Y")) -> 7.7534247 | N30: =L30+M30 -> 9.7534247 | O30: Admin | P30: 34206 | Q30: Male | T30: =IF(D30="","No","Yes") -> No | U30: Referrals | V30: 44 | W30: B+ | X30: Married | Y30: Address | Z30: 5132664546 | AA30: 3 | AB30: MBA | AC30: region_7 | AD30: SAP Controls Transformation
A31: E158 | B31: CYNTHIA HAMOR | C31: 42394 | E31: L4 | F31: BI | G31: Employees | H31: Active | I31: Confirmed | J31: Pune | K31: 42461 | L31: 2.8 | M31: =IF(H31<>"03 Exit",(TODAY()-C31)/365,DATEDIF(C31,D31,"Y")) -> 7.6876712 | N31: =L31+M31 -> 10.487671 | O31: IT | P31: 32910 | Q31: Male | T31: =IF(D31="","No","Yes") -> No | U31: Referrals | V31: 30 | W31: AB+ | X31: Married | Y31: Address | Z31: 6183121500 | AA31: 3 | AB31: MBA | AC31: region_13 | AD31: TPA
A32: E181 | B32: DALE VANDEVENTER | C32: 42522 | E32: L3 | F32: BI | G32: Employees | H32: Active | I32: Confirmed | J32: Pune | K32: 42614 | L32: 2.5 | M32: =IF(H32<>"03 Exit",(TODAY()-C32)/365,DATEDIF(C32,D32,"Y")) -> 7.3369863 | N32: =L32+M32 -> 9.8369863 | P32: 32172 | Q32: Female | T32: =IF(D32="","No","Yes") -> No | U32: Referrals | V32: 27 | W32: A+ | X32: Married | Y32: Address | Z32: 5360230333 | AA32: 3 | AB32: Bachelor's | AC32: region_15 | AD32: Python Engineer, Data science and ETL
A33: E192 | B33: DANIEL WORTHINGTON | C33: 42552 | E33: L3 | F33: BI | G33: Employees | H33: Active | I33: Confirmed | J33: Pune | K33: 42644 | L33: 0 | M33: =IF(H33<>"03 Exit",(TODAY()-C33)/365,DATEDIF(C33,D33,"Y")) -> 7.2547945 | N33: =L33+M33 -> 7.2547945 | O33: VFS Project | P33: 34222 | Q33: Male | T33: =IF(D33="","No","Yes") -> No | U33: job boards | V33: 34 | W33: B- | X33: Unmarried | Y33: Address | Z33: 4525787344 | AA33: 3 | AB33: MBA | AC33: region_13 | AD33: Python Engineer, Data science and ETL
A34: E196 | B34: MARIA JONES | C34: 42552 | D34: 44320 | E34: L2 | F34: Cloud | G34: Employees | H34: 03 Exit | J34: PUNE | M34: =IF(H34<>"03 Exit",(TODAY()-C34)/365,DATEDIF(C34,D34,"Y")) -> 4 | Q34: Female | R34: Voluntary | S34: Growth Opportunities | T34: =IF(D34="","No","Yes") -> Yes | U34: Social media | V34: 44 | W34: O+ | X34: Married | Y34: Address | Z34: 1117655842 | AA34: 3 | AB34: Bachelor's | AC34: region_22 | AD34: Cloud Computing
A35: E198 | B35: DANNY WILLIAMS | C35: 42552 | E35: L3 | F35: BI | G35: Employees | H35: Active | I35: Confirmed | J35: Pune | K35: 42644 | L35: 0 | M35: =IF(H35<>"03 Exit",(TODAY()-C35)/365,DATEDIF(C35,D35,"Y")) -> 7.2547945 | N35: =L35+M35 -> 7.2547945 | O35: IT | P35: 34458 | Q35: Male | T35: =IF(D35="","No","Yes") -> No | U35: job boards | V35: 44 | W35: B+ | X35: Unmarried | Y35: Address | Z35: 9289938852 | AA35: 3 | AB35: Master's | AC35: region_15 | AD35: Python Engineer, Data science and ETL
A36: E201 | B36: SHAWN PETTIT | C36: 42555 | D36: 44417 | E36: L2 | F36: BI | G36: Employees | H36: 03 Exit | J36: PUNE | M36: =IF(H36<>"03 Exit",(TODAY()-C36)/365,DATEDIF(C36,D36,"Y")) -> 5 | Q36: Female | R36: Voluntary | S36: Growth Opportunities | T36: =IF(D36="","No","Yes") -> Yes | U36: Social media | V36: 36 | W36: O- | X36: Married | Y36: Address | Z36: 1924725075 | AA36: 3 | AB36: Master's | AC36: region_13 | AD36: Python Engineer, Data science and ETL
A37: E208 | B37: DARCI DURBIN | C37: 42569 | E37: L3 | F37: BI | G37: Employees | H37: Active | I37: Confirmed | J37: Pune | K37: 42675 | L37: 1 | M37: =IF(H37<>"03 Exit",(TODAY()-C37)/365,DATEDIF(C37,D37,"Y")) -> 7.2082192 | N37: =L37+M37 -> 8.2082192 | O37: GS Labs | P37: 32916 | Q37: Male | T37: =IF(D37="","No","Yes") -> No | U37: job boards | V37: 48 | W37: A+ | X37: Married | Y37: Address | Z37: 9346886405 | AA37: 3 | AB37: Bachelor's | AC37: region_7 | AD37: Python Engineer, Data science and ETL
A38: E210 | B38: DAVID KELM | C38: 42569 | E38: L5 | F38: BI | G38: Employees | H38: Active | I38: Confirmed | J38: Bengaluru | K38: 42675 | L38: 13 | M38: =IF(H38<>"03 Exit",(TODAY()-C38)/365,DATEDIF(C38,D38,"Y")) -> 7.2082192 | N38: =L38+M38 -> 20.208219 | O38: IT | P38: 29602 | Q38: Male | T38: =IF(D38="","No","Yes") -> No | U38: job boards | V38: 23 | W38: A+ | X38: Married | Y38: Address | Z38: 5041342834 | AA38: 3 | AB38: Master's | AC38: region_2 | AD38: IAM - Multiple Product
A39: E214 | B39: DAVID PAINE | C39: 42583 | E39: L4 | F39: BI | G39: Employees | H39: Active | I39: Confirmed | J39: Pune | K39: 42705 | L39: 1 | M39: =IF(H39<>"03 Exit",(TODAY()-C39)/365,DATEDIF(C39,D39,"Y")) -> 7.169863 | N39: =L39+M39 -> 8.169863 | O39: Eureka Forbes | P39: 34048 | Q39: Male | T39: =IF(D39="","No","Yes") -> No | U39: job boards | V39: 43 | W39: AB- | X39: Unmarried | Y39: Address | Z39: 6362281905 | AA39: 3 | AB39: Master's | AC39: region_7 | AD39: TPA
A40: E230 | B40: DEBBIE HAMM | C40: 42625 | E40: L4 | F40: BI | G40: Employees | H40: Active | I40: Confirmed | J40: Pune | K40: 42767 | L40: 3 | M40: =IF(H40<>"03 Exit",(TODAY()-C40)/365,DATEDIF(C40,D40,"Y")) -> 7.0547945 | N40: =L40+M40 -> 10.054795 | P40: 33096 | Q40: Male | T40: =IF(D40="","No","Yes") -> No | U40: Referrals | V40: 37 | W40: A+ | X40: Unmarried | Y40: Address | Z40: 4445160441 | AA40: 3 | AB40: Bachelor's | AC40: region_7 | AD40: TPA
...

Sheet Employee Rating
A1: EMP ID | B1: Date | C1: Employee Satisfaction | D1: PerformanceRating | E1: NPS | F1: Annual Increment
A2: E7 | B2: 44280 | C2: 3 | D2: 3 | E2: 7 | F2: =_xlfn.SWITCH(D2,5,20,4,16,3,13,2,10,1,7) -> 13
A3: E12 | B3: 44280 | C3: 4 | D3: 4 | E3: 7 | F3: =_xlfn.SWITCH(D3,5,20,4,16,3,13,2,10,1,7) -> 16
A4: E14 | B4: 44280 | C4: 2 | D4: 3 | E4: 7 | F4: =_xlfn.SWITCH(D4,5,20,4,16,3,13,2,10,1,7) -> 13
A5: E15 | B5: 44280 | C5: 3 | D5: 3 | E5: 4 | F5: =_xlfn.SWITCH(D5,5,20,4,16,3,13,2,10,1,7) -> 13
A6: E24 | B6: 44280 | C6: 2 | D6: 3 | E6: 8 | F6: =_xlfn.SWITCH(D6,5,20,4,16,3,13,2,10,1,7) -> 13
A7: E27 | B7: 44280 | C7: 4 | D7: 3 | E7: 6 | F7: =_xlfn.SWITCH(D7,5,20,4,16,3,13,2,10,1,7) -> 13
A8: E36 | B8: 44280 | C8: 5 | D8: 4 | E8: 8 | F8: =_xlfn.SWITCH(D8,5,20,4,16,3,13,2,10,1,7) -> 16
A9: E38 | B9: 44280 | C9: 3 | D9: 4 | E9: 8 | F9: =_xlfn.SWITCH(D9,5,20,4,16,3,13,2,10,1,7) -> 16
A10: E53 | B10: 44280 | C10: 3 | D10: 4 | E10: 3 | F10: =_xlfn.SWITCH(D10,5,20,4,16,3,13,2,10,1,7) -> 16
A11: E56 | B11: 44280 | C11: 3 | D11: 3 | E11: 9 | F11: =_xlfn.SWITCH(D11,5,20,4,16,3,13,2,10,1,7) -> 13
A12: E62 | B12: 44280 | C12: 2 | D12: 3 | E12: 8 | F12: =_xlfn.SWITCH(D12,5,20,4,16,3,13,2,10,1,7) -> 13
A13: E63 | B13: 44280 | C13: 3 | D13: 3 | E13: 6 | F13: =_xlfn.SWITCH(D13,5,20,4,16,3,13,2,10,1,7) -> 13
... A829: E2001 | B829: 44640 | C829: 4 | D829: 4 | E829: 10 | F829: =_xlfn.SWITCH(D829,5,20,4,16,3,13,2,10,1,7) -> 16

Sheet Requesition Details
A1: S.No | B1: Skills | C1: Date | D1: Department | E1: Project Name | F1: Experience range | G1: Level | H1: Location | I1: No. of Openings
A2: 1 | B2: Senior Technical Consultant | C2: 44801 | D2: Support | E2: DHFL | F2: 3 to 6 yrs | G2: L2 | H2: Pune/Mumbai | I2: 5
A3: 2 | B3: Python | C3: 44806 | D3: BI | E3: Cigna | F3: 1 to 3 yrs | G3: L2 | H3: Pune/Mumbai | I3: 3
A4: 3 | B4: Python | C4: 44806 | D4: BI | E4: DHFL | F4: 1 to 3 yrs | G4: L2 | H4: Pune/Mumbai | I4: 3
A5: 4 | B5: Python | C5: 44806 | D5: BI | E5: Adobe | F5: 1 to 3 yrs | G5: L1 | H5: Pune/Mumbai | I5: 1
A6: 5 | B6: Python | C6: 44819 | D6: BI | E6: Maruti Suzuki | F6: 1 to 4 yrs | G6: L2 | H6: Pune | I6: 8
A7: 6 | B7: Senior Technical Consultant | C7: 44819 | D7: Support | E7: Accounts | F7: 3 to 6 yrs | G7: L2 | H7: Bengaluru | I7: 5
A8: 7 | B8: Test Lead | C8: 44788 | D8: QA & QC | E8: DHFL | F8: 8+yrs | G8: L3/ L4 | H8: Pune | I8: 2
A9: 8 | B9: Senior Technical Consultant | C9: 44812 | D9: Support | E9: Admin | F9: 4 to 6 yrs | G9: L2 | H9: Chennai | I9: 5
A10: 9 | B10: Technical Lead | C10: 44783 | D10: Support | E10: HR | F10: 8 + yrs | G10: L3/ L4 | H10: Pune/Mumbai | I10: 2
A11: 10 | B11: Senior Associate | C11: 44767 | D11: Sales | E11: DHFL | F11: 3-7 yrs | G11: L3 | H11: Chennai | I11: 2
A12: 11 | B12: Senior Associate | C12: 44802 | D12: Sales | E12: Shopper Stop | F12: 3-7 yrs | G12: L3 | H12: Pune | I12: 1
A13: 12 | B13: Technical Lead | C13: 44783 | D13: BI | E13: Shopper Stop | F13: 2 to 5 yrs | G13: L1 | H13: Chennai | I13: 15
... A26: 25 | B26: Technical Lead | C26: 44828 | D26: Support | E26: Shopper Stop | F26: 8 + yrs | G26: L3/ L4 | H26: Chennai | I26: 2

Sheet Training
A1: Emp Id | B1: Level | C1: Date | D1: Training Course Name | E1: Training Status | F1: Dept | G1: Start Date Time | H1: End Date Time | I1: Training Budget | J1: Actual Cost | K1: Training Hours Target | L1: Training Hours
A2: E24 | B2: L5 | C2: 44347 | D2: Management Training | E2: Completed | F2: BI | G2: 44508.498 | H2: =G2+K2/12 -> 44522.665 | I2: 10000 | J2: 8500 | K2: 170 | L2: 96
A3: E36 | B3: L4 | C3: 44355 | D3: Team Management | E3: Not started | F3: Cloud | G3: 44770.658 | H3: =G3+K3/12 -> 44785.658 | I3: 3999 | K3: 180
A4: E38 | B4: L5 | C4: 44442 | D4: Management Training | E4: Not started | F4: BI | G4: 44815.346 | H4: =G4+K4/12 -> 44829.512 | I4: 10000 | K4: 170
A5: E53 | B5: L4 | C5: 44442 | D5: Management Training | E5: Completed | F5: BI | G5: 44508.498 | H5: =G5+K5/12 -> 44522.665 | I5: 10000 | J5: 9000 | K5: 170 | L5: 126
A6: E56 | B6: L4 | C6: 44397 | D6: Management Training | E6: Unfinished | F6: BI | G6: 44675.414 | H6: =G6+K6/12 -> 44689.581 | I6: 10000 | J6: 4000 | K6: 170 | L6: 115
A7: E62 | B7: L4 | C7: 44426 | D7: Management Training | E7: Unfinished | F7: BI | G7: 44675.414 | H7: =G7+K7/12 -> 44689.581 | I7: 10000 | J7: 4000 | K7: 170 | L7: 85
A8: E63 | B8: L5 | C8: 44187 | D8: Management Training | E8: Not started | F8: BI | G8: 44815.346 | H8: =G8+K8/12 -> 44829.512 | I8: 10000 | K8: 170
A9: E64 | B9: L4 | C9: 44177 | D9: Management Training | E9: Completed | F9: BI | G9: 44508.498 | H9: =G9+K9/12 -> 44522.665 | I9: 10000 | J9: 9000 | K9: 170 | L9: 156
A10: E76 | B10: L6 | C10: 44360 | D10: Management Training | E10: Completed | F10: BI | G10: 44508.498 | H10: =G10+K10/12 -> 44522.665 | I10: 10000 | J10: 9000 | K10: 170 | L10: 138
A11: E89 | B11: L4 | C11: 44469 | D11: Management Training | E11: Not started | F11: BI | G11: 44815.346 | H11: =G11+K11/12 -> 44829.512 | I11: 10000 | J11: 7600 | K11: 170
A12: E98 | B12: L4 | C12: 44259 | D12: Management Training | E12: Completed | F12: BI | G12: 44508.498 | H12: =G12+K12/12 -> 44522.665 | I12: 10000 | J12: 9080 | K12: 170 | L12: 137
A13: E99 | B13: L5 | C13: 44366 | D13: Synapse | E13: Not started | F13: BI | G13: 44770.658 | H13: =G13+K13/12 -> 44790.242 | I13: 8000 | K13: 235
A14: E100 | B14: L6 | C14: 44311 | D14: Synapse | E14: Completed | F14: BI | G14: 44563.664 | H14: =G14+K14/12 -> 44583.247 | I14: 8000 | J14: 7000 | K14: 235 | L14: 196
A15: E115 | B15: L4 | C15: 44324 | D15: Customer Services | E15: Completed | F15: Support | G15: 44508.498 | H15: =G15+K15/12 -> 44526.832 | I15: 7900 | J15: 6800 | K15: 220 | L15: 170
A16: E116 | B16: L4 | C16: 44273 | D16: Synapse | E16: Not started | F16: BI | G16: 44770.658 | H16: =G16+K16/12 -> 44790.242 | I16: 8000 | K16: 235
A17: E127 | B17: L5 | C17: 44241 | D17: Synapse | E17: Not started | F17: BI | G17: 44770.658 | H17: =G17+K17/12 -> 44790.242 | I17: 8000 | K17: 235
A18: E131 | B18: L4 | C18: 44408 | D18: Synapse | E18: Not started | F18: BI | G18: 44770.658 | H18: =G18+K18/12 -> 44790.242 | I18: 8000 | K18: 235
A19: E135 | B19: L4 | C19: 44507 | D19: Project Management | E19: Unfinished | F19: QA & QC | G19: 44709.426 | H19: =G19+K19/12 -> 44719.426 | I19: 9000 | J19: 5999 | K19: 120 | L19: 112
A20: E138 | B20: L5 | C20: 44509 | D20: Synapse | E20: Completed | F20: BI | G20: 44563.664 | H20: =G20+K20/12 -> 44583.247 | I20: 8000 | J20: 7600 | K20: 235 | L20: 125
A21: E145 | B21: L3 | C21: 44430 | D21: Python | E21: Unfinished | F21: BI | G21: 44709.426 | H21: =G21+K21/12 -> 44728.593 | I21: 5000 | J21: 300 | K21: 230 | L21: 191
A22: E150 | B22: L3 | C22: 44388 | D22: Testing | E22: Completed | F22: QA & QC | G22: 44563.664 | H22: =G22+K22/12 -> 44583.58 | I22: 13000 | J22: 12000 | K22: 239 | L22: 175
A23: E156 | B23: L1 | C23: 44339 | D23: CRM D365 | E23: Not started | F23: Support | G23: 44824.623 | H23: =G23+K23/12 -> 44843.789 | I23: 7888 | K23: 230
A24: E158 | B24: L4 | C24: 44297 | D24: Synapse | E24: Unfinished | F24: BI | G24: 44658.643 | H24: =G24+K24/12 -> 44678.226 | I24: 8000 | J24: 6000 | K24: 235 | L24: 159
A25: E181 | B25: L3 | C25: 44428 | D25: Python | E25: Completed | F25: BI | G25: 44417.438 | H25: =G25+K25/12 -> 44436.604 | I25: 5000 | J25: 6000 | K25: 230 | L25: 134
A26: E192 | B26: L3 | C26: 44230 | D26: Python | E26: Not started | F26: BI | G26: 44767.487 | H26: =G26+K26/12 -> 44786.653 | I26: 5000 | K26: 230
A27: E198 | B27: L3 | C27: 44283 | D27: Python | E27: Not started | F27: BI | G27: 44767.487 | H27: =G27+K27/12 -> 44786.653 | I27: 5000 | K27: 230
A28: E208 | B28: L3 | C28: 44414 | D28: Python | E28: Not started | F28: BI | G28: 44767.487 | H28: =G28+K28/12 -> 44786.653 | I28: 5000 | K28: 230
A29: E210 | B29: L5 | C29: 44208 | D29: Synapse | E29: Completed | F29: BI | G29: 44563.664 | H29: =G29+K29/12 -> 44583.247 | I29: 8000 | J29: 8000 | K29: 235 | L29: 154
A30: E214 | B30: L4 | C30: 44468 | D30: Synapse | E30: Unfinished | F30: BI | G30: 44658.643 | H30: =G30+K30/12 -> 44678.226 | I30: 8000 | J30: 5000 | K30: 235 | L30: 148
A31: E230 | B31: L4 | C31: 44246 | D31: Synapse | E31: Unfinished | F31: BI | G31: 44658.643 | H31: =G31+K31/12 -> 44678.226 | I31: 8000 | J31: 5000 | K31: 235 | L31: 111
A32: E236 | B32: L5 | C32: 44206 | D32: Synapse | E32: Unfinished | F32: BI | G32: 44658.643 | H32: =G32+K32/12 -> 44678.226 | I32: 8000 | J32: 5000 | K32: 235 | L32: 93
A33: E243 | B33: L5 | C33: 44343 | D33: Synapse | E33: Not started | F33: BI | G33: 44770.658 | H33: =G33+K33/12 -> 44790.242 | I33: 8000 | K33: 235
A34: E247 | B34: L4 | C34: 44517 | D34: SQL | E34: Not started | F34: BI | G34: 44777.688 | H34: =G34+K34/12 -> 44796.021 | I34: 4500 | K34: 220
A35: E251 | B35: L2 | C35: 44456 | D35: Python | E35: Not started | F35: BI | G35: 44767.487 | H35: =G35+K35/12 -> 44786.653 | I35: 5000 | K35: 230
A36: E259 | B36: L3 | C36: 44375 | D36: Python | E36: Unfinished | F36: BI | G36: 44709.426 | H36: =G36+K36/12 -> 44728.593 | I36: 5000 | J36: 500 | K36: 230 | L36: 193
A37: E262 | B37: L2 | C37: 44408 | D37: Cloud Fundamentals | E37: Unfinished | F37: Cloud | G37: 44675.414 | H37: =G37+K37/12 -> 44686.247 | I37: 5999 | J37: 3999 | K37: 130 | L37: 188
A38: E266 | B38: L4 | C38: 44396 | D38: SQL | E38: Completed | F38: BI | G38: 44417.438 | H38: =G38+K38/12 -> 44435.771 | I38: 4500 | J38: 4300 | K38: 220 | L38: 200
A39: E272 | B39: L1 | C39: 44411 | D39: CRM D365 | E39: Unfinished | F39: Support | G39: 44675.414 | H39: =G39+K39/12 -> 44694.581 | I39: 7888 | J39: 6890 | K39: 230 | L39: 196
A40: E278 | B40: L3 | C40: 44406 | D40: Python | E40: Unfinished | F40: BI | G40: 44709.426 | H40: =G40+K40/12 -> 44728.593 | I40: 5000 | J40: 3600 | K40: 230 | L40: 198
...

Sheet Joining Details
A1: Sr No | B1: Offer No | C1: Status | D1: Total Exp (in ) | E1: Relevant (in ) | F1: Skill | G1: Function | H1: Qualification | I1: D O O | J1: DOJ | K1: Job Location
B2: 700 | C2: YTJ | D2: 1 | E2: 1 | F2: MS CRM | G2: D365 CRM | H2: BE | I2: 44406 | J2: 44621 | K2: Pune
B3: 785 | C3: YTJ | D3: 2.7 | E3: 2.7 | F3: Dotnet | G3: D365 CRM | H3: BE IT | I3: 44477 | J3: 44562 | K3: Pune
B4: 795 | C4: Joined | D4: 4 | E4: 4 | F4: Application Support | G4: AMS | H4: MCA | I4: 44512 | J4: 44562 | K4: Pune
B5: 808 | C5: YTJ | D5: 2.5 | E5: 2.5 | F5: QA Automation | G5: QA & QC | H5: Bsc | I5: 44524 | J5: 44562 | K5: Pune
B6: 811 | C6: YTJ | D6: 7 | E6: 7 | F6: BA | G6: QA & QC | H6: B-Tech | I6: 44525 | J6: 44562 | K6: Bengaluru
B7: 829 | C7: YTJ | D7: 1.2 | E7: 1.2 | F7: Dotnet | G7: D365 CRM | H7: BTech | I7: 44544 | J7: 44562 | K7: Pune
B8: 871 | C8: YTJ | D8: 7 | E8: 5 | F8: Application Support | G8: AMS | H8: BTech | I8: 44558 | J8: 44562 | K8: Gurugram
B9: 873 | C9: YTJ | D9: 1 | E9: 1 | F9: Recuritment | G9: Recruitment | H9: MBA | I9: 44201 | J9: 44562 | K9: Chennai
B10: 874 | C10: YTJ | D10: 5 | E10: 5 | F10: QA Manual | G10: QA & QC | H10: BE | I10: 44566 | J10: 44562 | K10: Pune
B11: 875 | C11: Joined | D11: 3.11 | E11: 3.5 | F11: Application Support | G11: AMS | H11: BE | I11: 44567 | J11: 44562 | K11: Pune
B12: 876 | C12: Joined | D12: 1.3 | E12: 1.3 | F12: Dotnet | G12: D365 CRM | H12: BE | I12: 44567 | J12: 44562 | K12: Pune
B13: 877 | C13: YTJ | D13: 3.8 | E13: 3.8 | F13: Application Support | G13: AMS | H13: BE | I13: 44568 | J13: 44562 | K13: Pune
... B18: 836 | C18: YTJ | D18: 3 | E18: 3 | F18: Dotnet | G18: D365 CRM | H18: BE | I18: 44544 | J18: 44621 | K18: Pune
B19: 838 | C19: YTJ | D19: 1.5 | E19: 1.5 | F19: Dotnet | G19: D365 CRM | I19: 44544 | J19: 44621 | K19: Pune
B20: 851 | C20: YTJ | D20: 6.4 | E20: 6.4 | F20: Dotnet | G20: D365 CRM | H20: MCA | I20: 44550 | J20: 44593 | K20: Pune
B21: 869 | C21: YTJ | D21: 3.7 | E21: 3.2 | F21: Application Support | G21: AMS | H21: BE | I21: 44554 | J21: 44621 | K21: Chennai

Sheet Salary
A1: Emp_Id | B1: Level | C1: Basic Salary | D1: DA | E1: HRA | F1: PF | G1: Gross Salary | H1: EPF | I1: LIC | J1: Total Deduction | K1: Net Salary | L1: CTC | M1: Bonus | N1: Overtime
A2: E7 | B2: L8 | C2: 90000 | D2: =C2*10/100 -> 9000 | E2: =C2*7.5/100 -> 6750 | F2: =C2*15/100 -> 13500 | G2: =SUM(C2:F2) -> 119250 | H2: =F2/2 -> 6750 | I2: =H2/2 -> 3375 | J2: =SUM(H2:I2) -> 10125 | K2: =G2-J2 -> 109125 | L2: =G2*12 -> 1431000 | M2: 30000 | N2: 33521
A3: E12 | B3: L8 | C3: 77000 | D3: =C3*10/100 -> 7700 | E3: =C3*7.5/100 -> 5775 | F3: =C3*15/100 -> 11550 | G3: =SUM(C3:F3) -> 102025 | H3: =F3/2 -> 5775 | I3: =H3/2 -> 2887.5 | J3: =SUM(H3:I3) -> 8662.5 | K3: =G3-J3 -> 93362.5 | L3: =G3*12 -> 1224300 | M3: 30000 | N3: 42421
A4: E14 | B4: L8 | C4: 95000 | D4: =C4*10/100 -> 9500 | E4: =C4*7.5/100 -> 7125 | F4: =C4*15/100 -> 14250 | G4: =SUM(C4:F4) -> 125875 | H4: =F4/2 -> 7125 | I4: =H4/2 -> 3562.5 | J4: =SUM(H4:I4) -> 10687.5 | K4: =G4-J4 -> 115187.5 | L4: =G4*12 -> 1510500 | M4: 30000 | N4: 34507
A5: E15 | B5: L8 | C5: 80000 | D5: =C5*10/100 -> 8000 | E5: =C5*7.5/100 -> 6000 | F5: =C5*15/100 -> 12000 | G5: =SUM(C5:F5) -> 106000 | H5: =F5/2 -> 6000 | I5: =H5/2 -> 3000 | J5: =SUM(H5:I5) -> 9000 | K5: =G5-J5 -> 97000 | L5: =G5*12 -> 1272000 | M5: 30000 | N5: 42828
A6: E24 | B6: L5 | C6: 60000 | D6: =C6*10/100 -> 6000 | E6: =C6*7.5/100 -> 4500 | F6: =C6*15/100 -> 9000 | G6: =SUM(C6:F6) -> 79500 | H6: =F6/2 -> 4500 | I6: =H6/2 -> 2250 | J6: =SUM(H6:I6) -> 6750 | K6: =G6-J6 -> 72750 | L6: =G6*12 -> 954000 | M6: 25000 | N6: 40165
A7: E27 | B7: L8 | C7: 77000 | D7: =C7*10/100 -> 7700 | E7: =C7*7.5/100 -> 5775 | F7: =C7*15/100 -> 11550 | G7: =SUM(C7:F7) -> 102025 | H7: =F7/2 -> 5775 | I7: =H7/2 -> 2887.5 | J7: =SUM(H7:I7) -> 8662.5 | K7: =G7-J7 -> 93362.5 | L7: =G7*12 -> 1224300 | M7: 30000 | N7: 45286
A8: E36 | B8: L4 | C8: 45000 | D8: =C8*10/100 -> 4500 | E8: =C8*7.5/100 -> 3375 | F8: =C8*15/100 -> 6750 | G8: =SUM(C8:F8) -> 59625 | H8: =F8/2 -> 3375 | I8: =H8/2 -> 1687.5 | J8: =SUM(H8:I8) -> 5062.5 | K8: =G8-J8 -> 54562.5 | L8: =G8*12 -> 715500 | M8: 20000 | N8: 46317
A9: E38 | B9: L5 | C9: 60000 | D9: =C9*10/100 -> 6000 | E9: =C9*7.5/100 -> 4500 | F9: =C9*15/100 -> 9000 | G9: =SUM(C9:F9) -> 79500 | H9: =F9/2 -> 4500 | I9: =H9/2 -> 2250 | J9: =SUM(H9:I9) -> 6750 | K9: =G9-J9 -> 72750 | L9: =G9*12 -> 954000 | M9: 25000 | N9: 37504
A10: E53 | B10: L4 | C10: 45000 | D10: =C10*10/100 -> 4500 | E10: =C10*7.5/100 -> 3375 | F10: =C10*15/100 -> 6750 | G10: =SUM(C10:F10) -> 59625 | H10: =F10/2 -> 3375 | I10: =H10/2 -> 1687.5 | J10: =SUM(H10:I10) -> 5062.5 | K10: =G10-J10 -> 54562.5 | L10: =G10*12 -> 715500 | M10: 20000 | N10: 41411
A11: E56 | B11: L4 | C11: 45000 | D11: =C11*10/100 -> 4500 | E11: =C11*7.5/100 -> 3375 | F11: =C11*15/100 -> 6750 | G11: =SUM(C11:F11) -> 59625 | H11: =F11/2 -> 3375 | I11: =H11/2 -> 1687.5 | J11: =SUM(H11:I11) -> 5062.5 | K11: =G11-J11 -> 54562.5 | L11: =G11*12 -> 715500 | M11: 20000 | N11: 47458
A12: E62 | B12: L4 | C12: 45000 | D12: =C12*10/100 -> 4500 | E12: =C12*7.5/100 -> 3375 | F12: =C12*15/100 -> 6750 | G12: =SUM(C12:F12) -> 59625 | H12: =F12/2 -> 3375 | I12: =H12/2 -> 1687.5 | J12: =SUM(H12:I12) -> 5062.5 | K12: =G12-J12 -> 54562.5 | L12: =G12*12 -> 715500 | M12: 20000 | N12: 21900
A13: E63 | B13: L5 | C13: 60000 | D13: =C13*10/100 -> 6000 | E13: =C13*7.5/100 -> 4500 | F13: =C13*15/100 -> 9000 | G13: =SUM(C13:F13) -> 79500 | H13: =F13/2 -> 4500 | I13: =H13/2 -> 2250 | J13: =SUM(H13:I13) -> 6750 | K13: =G13-J13 -> 72750 | L13: =G13*12 -> 954000 | M13: 25000 | N13: 23721
... A45: E278 | B45: L3 | C45: 26000 | D45: =C45*10/100 -> 2600 | E45: =C45*7.5/100 -> 1950 | F45: =C45*15/100 -> 3900 | G45: =SUM(C45:F45) -> 34450 | H45: =F45/2 -> 1950 | I45: =H45/2 -> 975 | J45: =SUM(H45:I45) -> 2925 | K45: =G45-J45 -> 31525 | L45: =G45*12 -> 413400 | M45: 20000 | N45: 20370
A46: E283 | B46: L3 | C46: 26000 | D46: =C46*10/100 -> 2600 | E46: =C46*7.5/100 -> 1950 | F46: =C46*15/100 -> 3900 | G46: =SUM(C46:F46) -> 34450 | H46: =F46/2 -> 1950 | I46: =H46/2 -> 975 | J46: =SUM(H46:I46) -> 2925 | K46: =G46-J46 -> 31525 | L46: =G46*12 -> 413400 | M46: 20000
A47: E298 | B47: L3 | C47: 26000 | D47: =C47*10/100 -> 2600 | E47: =C47*7.5/100 -> 1950 | F47: =C47*15/100 -> 3900 | G47: =SUM(C47:F47) -> 34450 | H47: =F47/2 -> 1950 | I47: =H47/2 -> 975 | J47: =SUM(H47:I47) -> 2925 | K47: =G47-J47 -> 31525 | L47: =G47*12 -> 413400 | M47: 20000
A48: E307 | B48: L3 | C48: 30000 | D48: =C48*10/100 -> 3000 | E48: =C48*7.5/100 -> 2250 | F48: =C48*15/100 -> 4500 | G48: =SUM(C48:F48) -> 39750 | H48: =F48/2 -> 2250 | I48: =H48/2 -> 1125 | J48: =SUM(H48:I48) -> 3375 | K48: =G48-J48 -> 36375 | L48: =G48*12 -> 477000 | M48: 20000
A49: E308 | B49: L2 | C49: 25000 | D49: =C49*10/100 -> 2500 | E49: =C49*7.5/100 -> 1875 | F49: =C49*15/100 -> 3750 | G49: =SUM(C49:F49) -> 33125 | H49: =F49/2 -> 1875 | I49: =H49/2 -> 937.5 | J49: =SUM(H49:I49) -> 2812.5 | K49: =G49-J49 -> 30312.5 | L49: =G49*12 -> 397500 | M49: 15000
A50: E315 | B50: L1 | C50: 20000 | D50: =C50*10/100 -> 2000 | E50: =C50*7.5/100 -> 1500 | F50: =C50*15/100 -> 3000 | G50: =SUM(C50:F50) -> 26500 | H50: =F50/2 -> 1500 | I50: =H50/2 -> 750 | J50: =SUM(H50:I50) -> 2250 | K50: =G50-J50 -> 24250 | L50: =G50*12 -> 318000 | M50: 15000
A51: E323 | B51: L3 | C51: 30000 | D51: =C51*10/100 -> 3000 | E51: =C51*7.5/100 -> 2250 | F51: =C51*15/100 -> 4500 | G51: =SUM(C51:F51) -> 39750 | H51: =F51/2 -> 2250 | I51: =H51/2 -> 1125 | J51: =SUM(H51:I51) -> 3375 | K51: =G51-J51 -> 36375 | L51: =G51*12 -> 477000 | M51: 20000
A52: E324 | B52: L3 | C52: 30000 | D52: =C52*10/100 -> 3000 | E52: =C52*7.5/100 -> 2250 | F52: =C52*15/100 -> 4500 | G52: =SUM(C52:F52) -> 39750 | H52: =F52/2 -> 2250 | I52: =H52/2 -> 1125 | J52: =SUM(H52:I52) -> 3375 | K52: =G52-J52 -> 36375 | L52: =G52*12 -> 477000 | M52: 20000
A53: E329 | B53: L5 | C53: 50000 | D53: =C53*10/100 -> 5000 | E53: =C53*7.5/100 -> 3750 | F53: =C53*15/100 -> 7500 | G53: =SUM(C53:F53) -> 66250 | H53: =F53/2 -> 3750 | I53: =H53/2 -> 1875 | J53: =SUM(H53:I53) -> 5625 | K53: =G53-J53 -> 60625 | L53: =G53*12 -> 795000 | M53: 25000
A54: E333 | B54: L4 | C54: 40000 | D54: =C54*10/100 -> 4000 | E54: =C54*7.5/100 -> 3000 | F54: =C54*15/100 -> 6000 | G54: =SUM(C54:F54) -> 53000 | H54: =F54/2 -> 3000 | I54: =H54/2 -> 1500 | J54: =SUM(H54:I54) -> 4500 | K54: =G54-J54 -> 48500 | L54: =G54*12 -> 636000 | M54: 20000
A55: E335 | B55: L2 | C55: 25000 | D55: =C55*10/100 -> 2500 | E55: =C55*7.5/100 -> 1875 | F55: =C55*15/100 -> 3750 | G55: =SUM(C55:F55) -> 33125 | H55: =F55/2 -> 1875 | I55: =H55/2 -> 937.5 | J55: =SUM(H55:I55) -> 2812.5 | K55: =G55-J55 -> 30312.5 | L55: =G55*12 -> 397500 | M55: 15000
A56: E337 | B56: L3 | C56: 30000 | D56: =C56*10/100 -> 3000 | E56: =C56*7.5/100 -> 2250 | F56: =C56*15/100 -> 4500 | G56: =SUM(C56:F56) -> 39750 | H56: =F56/2 -> 2250 | I56: =H56/2 -> 1125 | J56: =SUM(H56:I56) -> 3375 | K56: =G56-J56 -> 36375 | L56: =G56*12 -> 477000 | M56: 20000
A57: E350 | B57: L3 | C57: 30000 | D57: =C57*10/100 -> 3000 | E57: =C57*7.5/100 -> 2250 | F57: =C57*15/100 -> 4500 | G57: =SUM(C57:F57) -> 39750 | H57: =F57/2 -> 2250 | I57: =H57/2 -> 1125 | J57: =SUM(H57:I57) -> 3375 | K57: =G57-J57 -> 36375 | L57: =G57*12 -> 477000 | M57: 20000
A58: E355 | B58: L2 | C58: 25000 | D58: =C58*10/100 -> 2500 | E58: =C58*7.5/100 -> 1875 | F58: =C58*15/100 -> 3750 | G58: =SUM(C58:F58) -> 33125 | H58: =F58/2 -> 1875 | I58: =H58/2 -> 937.5 | J58: =SUM(H58:I58) -> 2812.5 | K58: =G58-J58 -> 30312.5 | L58: =G58*12 -> 397500 | M58: 15000
A59: E362 | B59: L6 | C59: 60000 | D59: =C59*10/100 -> 6000 | E59: =C59*7.5/100 -> 4500 | F59: =C59*15/100 -> 9000 | G59: =SUM(C59:F59) -> 79500 | H59: =F59/2 -> 4500 | I59: =H59/2 -> 2250 | J59: =SUM(H59:I59) -> 6750 | K59: =G59-J59 -> 72750 | L59: =G59*12 -> 954000 | M59: 25000 | N59: =RANDBETWEEN(30000,50000) -> 47262
A60: E366 | B60: L2 | C60: 25000 | D60: =C60*10/100 -> 2500 | E60: =C60*7.5/100 -> 1875 | F60: =C60*15/100 -> 3750 | G60: =SUM(C60:F60) -> 33125 | H60: =F60/2 -> 1875 | I60: =H60/2 -> 937.5 | J60: =SUM(H60:I60) -> 2812.5 | K60: =G60-J60 -> 30312.5 | L60: =G60*12 -> 397500 | M60: 15000 | N60: 8872
A61: E371 | B61: L5 | C61: 50000 | D61: =C61*10/100 -> 5000 | E61: =C61*7.5/100 -> 3750 | F61: =C61*15/100 -> 7500 | G61: =SUM(C61:F61) -> 66250 | H61: =F61/2 -> 3750 | I61: =H61/2 -> 1875 | J61: =SUM(H61:I61) -> 5625 | K61: =G61-J61 -> 60625 | L61: =G61*12 -> 795000 | M61: 25000 | N61: =RANDBETWEEN(20000,30000) -> 20551
A62: E378 | B62: L3 | C62: 30000 | D62: =C62*10/100 -> 3000 | E62: =C62*7.5/100 -> 2250 | F62: =C62*15/100 -> 4500 | G62: =SUM(C62:F62) -> 39750 | H62: =F62/2 -> 2250 | I62: =H62/2 -> 1125 | J62: =SUM(H62:I62) -> 3375 | K62: =G62-J62 -> 36375 | L62: =G62*12 -> 477000 | M62: 20000 | N62: 12222
A63: E381 | B63: L5 | C63: 50000 | D63: =C63*10/100 -> 5000 | E63: =C63*7.5/100 -> 3750 | F63: =C63*15/100 -> 7500 | G63: =SUM(C63:F63) -> 66250 | H63: =F63/2 -> 3750 | I63: =H63/2 -> 1875 | J63: =SUM(H63:I63) -> 5625 | K63: =G63-J63 -> 60625 | L63: =G63*12 -> 795000 | M63: 25000 | N63: =RANDBETWEEN(20000,30000) -> 20832
A64: E393 | B64: L3 | C64: 30000 | D64: =C64*10/100 -> 3000 | E64: =C64*7.5/100 -> 2250 | F64: =C64*15/100 -> 4500 | G64: =SUM(C64:F64) -> 39750 | H64: =F64/2 -> 2250 | I64: =H64/2 -> 1125 | J64: =SUM(H64:I64) -> 3375 | K64: =G64-J64 -> 36375 | L64: =G64*12 -> 477000 | M64: 20000 | N64: 14666
A65: E403 | B65: L5 | C65: 50000 | D65: =C65*10/100 -> 5000 | E65: =C65*7.5/100 -> 3750 | F65: =C65*15/100 -> 7500 | G65: =SUM(C65:F65) -> 66250 | H65: =F65/2 -> 3750 | I65: =H65/2 -> 1875 | J65: =SUM(H65:I65) -> 5625 | K65: =G65-J65 -> 60625 | L65: =G65*12 -> 795000 | M65: 25000 | N65: =RANDBETWEEN(20000,30000) -> 26554
A66: E404 | B66: L3 | C66: 30000 | D66: =C66*10/100 -> 3000 | E66: =C66*7.5/100 -> 2250 | F66: =C66*15/100 -> 4500 | G66: =SUM(C66:F66) -> 39750 | H66: =F66/2 -> 2250 | I66: =H66/2 -> 1125 | J66: =SUM(H66:I66) -> 3375 | K66: =G66-J66 -> 36375 | L66: =G66*12 -> 477000 | M66: 20000 | N66: 11408
A67: E408 | B67: L3 | C67: 30000 | D67: =C67*10/100 -> 3000 | E67: =C67*7.5/100 -> 2250 | F67: =C67*15/100 -> 4500 | G67: =SUM(C67:F67) -> 39750 | H67: =F67/2 -> 2250 | I67: =H67/2 -> 1125 | J67: =SUM(H67:I67) -> 3375 | K67: =G67-J67 -> 36375 | L67: =G67*12 -> 477000 | M67: 20000 | N67: 18519
A68: E414 | B68: L4 | C68: 40000 | D68: =C68*10/100 -> 4000 | E68: =C68*7.5/100 -> 3000 | F68: =C68*15/100 -> 6000 | G68: =SUM(C68:F68) -> 53000 | H68: =F68/2 -> 3000 | I68: =H68/2 -> 1500 | J68: =SUM(H68:I68) -> 4500 | K68: =G68-J68 -> 48500 | L68: =G68*12 -> 636000 | M68: 20000 | N68: =RANDBETWEEN(20000,30000) -> 24640
A69: E415 | B69: L2 | C69: 25000 | D69: =C69*10/100 -> 2500 | E69: =C69*7.5/100 -> 1875 | F69: =C69*15/100 -> 3750 | G69: =SUM(C69:F69) -> 33125 | H69: =F69/2 -> 1875 | I69: =H69/2 -> 937.5 | J69: =SUM(H69:I69) -> 2812.5 | K69: =G69-J69 -> 30312.5 | L69: =G69*12 -> 397500 | M69: 15000 | N69: 12165
A70: E418 | B70: L3 | C70: 30000 | D70: =C70*10/100 -> 3000 | E70: =C70*7.5/100 -> 2250 | F70: =C70*15/100 -> 4500 | G70: =SUM(C70:F70) -> 39750 | H70: =F70/2 -> 2250 | I70: =H70/2 -> 1125 | J70: =SUM(H70:I70) -> 3375 | K70: =G70-J70 -> 36375 | L70: =G70*12 -> 477000 | M70: 20000 | N70: 12348
A71: E421 | B71: L4 | C71: 40000 | D71: =C71*10/100 -> 4000 | E71: =C71*7.5/100 -> 3000 | F71: =C71*15/100 -> 6000 | G71: =SUM(C71:F71) -> 53000 | H71: =F71/2 -> 3000 | I71: =H71/2 -> 1500 | J71: =SUM(H71:I71) -> 4500 | K71: =G71-J71 -> 48500 | L71: =G71*12 -> 636000 | M71: 20000 | N71: =RANDBETWEEN(20000,30000) -> 26899
...

Sheet Offer Acceptance
A1: application_id | B1: candidate_name | C1: offer_date | D1: Department | E1: Source | F1: offer_status | G1: Joined Status
A2: 1 | B2: Eadie | C2: 44274 | D2: BI | E2: Referrals | F2: Offer Rejected
A3: 2 | B3: Mel | C3: 44247 | D3: BI | E3: Social media | F3: On Hold
A4: 3 | B4: Tilda | C4: 44583 | D4: BI | E4: Career Fairs | F4: Offer Accepted | G4: Joined
A5: 4 | B5: Elyn | C5: 44445 | D5: BI | E5: Career Fairs | F5: Not Offered
A6: 5 | B6: Wildon | C6: 44284 | D6: BI | E6: Referrals | F6: Counteroffer
A7: 6 | B7: Hakim | C7: 44447 | D7: BI | E7: Referrals | F7: Counteroffer
A8: 7 | B8: Evered | C8: 44586 | D8: BI | E8: Referrals | F8: On Hold
A9: 8 | B9: Walden | C9: 43847 | D9: BI | E9: Referrals | F9: Offer Rejected
A10: 9 | B10: Thaddeus | C10: 44248 | D10: BI | E10: Referrals | F10: Not Offered
A11: 10 | B11: Cynthea | C11: 44240 | D11: BI | E11: Referrals | F11: On Hold
A12: 11 | B12: Seymour | C12: 44564 | D12: BI | E12: Referrals | F12: Offer Accepted | G12: Joined
A13: 12 | B13: Savina | C13: 43837 | D13: BI | E13: Referrals | F13: Offer Accepted | G13: Joined
A14: 13 | B14: Abran | C14: 43919 | D14: BI | E14: Referrals | F14: Counteroffer
A15: 14 | B15: Paige | C15: 44233 | D15: BI | E15: Social media | F15: Offer Accepted | G15: Joined
A16: 15 | B16: Gusta | C16: 44591 | D16: BI | E16: Social media | F16: On Hold
A17: 16 | B17: Helen | C17: 44376 | D17: BI | E17: Social media | F17: Counteroffer
A18: 17 | B18: Marti | C18: 44412 | D18: BI | E18: Social media | F18: Offer Accepted | G18: Joined
A19: 18 | B19: Rip | C19: 43898 | D19: BI | E19: Social media | F19: Offer Accepted | G19: Not Joined
A20: 19 | B20: Allyson | C20: 44612 | D20: BI | E20: Social media | F20: Offer Accepted | G20: Not Joined
A21: 20 | B21: Ado | C21: 43843 | D21: BI | E21: Social media | F21: Not Offered
A22: 21 | B22: Sibylle | C22: 44462 | D22: BI | E22: Social media | F22: On Hold
A23: 22 | B23: Timothea | C23: 44579 | D23: BI | E23: Social media | F23: Offer Accepted | G23: Not Joined
A24: 23 | B24: Wilden | C24: 43899 | D24: BI | E24: Social media | F24: Counteroffer
A25: 24 | B25: Carter | C25: 44440 | D25: BI | E25: Social media | F25: Offer Accepted | G25: Not Joined
A26: 25 | B26: Shanan | C26: 44575 | D26: BI | E26: Social media | F26: Offer Rejected
A27: 26 | B27: Alanah | C27: 44563 | D27: BI | E27: Social media | F27: Counteroffer
A28: 27 | B28: Faye | C28: 43917 | D28: BI | E28: Social media | F28: Offer Rejected
A29: 28 | B29: Sansone | C29: 44476 | D29: BI | E29: Career Fairs | F29: On Hold
A30: 29 | B30: Enrica | C30: 44623 | D30: Sales | E30: Career Fairs | F30: On Hold
A31: 30 | B31: Hank | C31: 44246 | D31: Sales | E31: Career Fairs | F31: Offer Accepted | G31: Not Joined
A32: 31 | B32: Timotheus | C32: 44602 | D32: Sales | E32: Career Fairs | F32: Counteroffer
A33: 32 | B33: Shae | C33: 44642 | D33: Sales | E33: Career Fairs | F33: On Hold
A34: 33 | B34: Tabina | C34: 44517 | D34: Sales | E34: Career Fairs | F34: Counteroffer
A35: 34 | B35: Ambrose | C35: 44646 | D35: Sales | E35: Career Fairs | F35: On Hold
A36: 35 | B36: Jermaine | C36: 44326 | D36: Sales | E36: Career Fairs | F36: Offer Rejected
A37: 36 | B37: Adriaens | C37: 43831 | D37: Sales | E37: Career Fairs | F37: Offer Accepted | G37: Not Joined
A38: 37 | B38: Sal | C38: 44498 | D38: Sales | E38: Career Fairs | F38: Counteroffer
A39: 38 | B39: Ree | C39: 44636 | D39: Sales | E39: Career Fairs | F39: Not Offered
A40: 39 | B40: Jolynn | C40: 44361 | D40: Sales | E40: Career Fairs | F40: Offer Accepted | G40: Not Joined
...

Sheet Leave  Prediction
A1: Joining_Date | B1: Start_Date | C1: End_Date | D1: EMP_ID | E1: Reason_for_Leave | F1: Type_of_Leave | G1: Planned/Unplanned | H1: Status | I1: No_of_Leave | J1: Gap
A2: =VLOOKUP(D2,Transaction!$A$2:$C$477,3,0) -> 42725 | B2: 42830 | C2: 42830 | D2: E7 | E2: Family function | F2: Casual Leave | G2: Planned | H2: Approved | I2: =(C2-B2)+1 -> 1 | J2: =B2-A2 -> 105
A3: =VLOOKUP(D3,Transaction!$A$2:$C$477,3,0) -> 42726 | B3: 42831 | C3: 42831 | D3: E12 | E3: Sick Leave | F3: Sick Leave | G3: Unplanned | H3: Rejected | I3: =(C3-B3)+1 -> 1 | J3: =B3-A3 -> 105
A4: =VLOOKUP(D4,Transaction!$A$2:$C$477,3,0) -> 42728 | B4: 42837 | C4: 42839 | D4: E15 | E4: Sick Leave | F4: Sick Leave | G4: Planned | H4: Approved | I4: =(C4-B4)+1 -> 3 | J4: =B4-A4 -> 109
A5: =VLOOKUP(D5,Transaction!$A$2:$C$477,3,0) -> 42767 | B5: 42840 | C5: 42840 | D5: E24 | E5: Documentation Work | F5: Paid Leave | G5: Planned | H5: Rejected | I5: =(C5-B5)+1 -> 1 | J5: =B5-A5 -> 73
A6: =VLOOKUP(D6,Transaction!$A$2:$C$477,3,0) -> 42727 | B6: 42845 | C6: 42847 | D6: E14 | E6: Family Outing | F6: Casual Leave | G6: Unplanned | H6: Approved | I6: =(C6-B6)+1 -> 3 | J6: =B6-A6 -> 118
A7: =VLOOKUP(D7,Transaction!$A$2:$C$477,3,0) -> 42691 | B7: 42850 | C7: 42853 | D7: E100 | E7: Personal Reason | F7: Casual Leave | G7: Planned | H7: Approved | I7: =(C7-B7)+1 -> 4 | J7: =B7-A7 -> 159
A8: =VLOOKUP(D8,Transaction!$A$2:$C$477,3,0) -> 42725 | B8: 42874 | C8: 42874 | D8: E7 | E8: Sick Leave | F8: Sick Leave | G8: Unplanned | H8: Approved | I8: =(C8-B8)+1 -> 1 | J8: =B8-B2 -> 44
A9: =VLOOKUP(D9,Transaction!$A$2:$C$477,3,0) -> 42726 | B9: 42876 | C9: 42876 | D9: E12 | E9: Family function | F9: Casual Leave | G9: Planned | H9: Approved | I9: =(C9-B9)+1 -> 1 | J9: =B9-B3 -> 45
A10: =VLOOKUP(D10,Transaction!$A$2:$C$477,3,0) -> 42727 | B10: 42876 | C10: 42876 | D10: E14 | E10: Sick Leave | F10: Sick Leave | G10: Unplanned | H10: Rejected | I10: =(C10-B10)+1 -> 1 | J10: =B10-B6 -> 31
A11: =VLOOKUP(D11,Transaction!$A$2:$C$477,3,0) -> 42728 | B11: 42879 | C11: 42879 | D11: E15 | E11: Personal Reason | F11: Casual Leave | G11: Unplanned | H11: Approved | I11: =(C11-B11)+1 -> 1 | J11: =B11-B4 -> 42
A12: =VLOOKUP(D12,Transaction!$A$2:$C$477,3,0) -> 42767 | B12: 42883 | C12: 42883 | D12: E24 | E12: Family Outing | F12: Paid Leave | G12: Planned | H12: Approved | I12: =(C12-B12)+1 -> 1 | J12: =B12-B5 -> 43
A13: =VLOOKUP(D13,Transaction!$A$2:$C$477,3,0) -> 42725 | B13: 42914 | C13: 42914 | D13: E7 | E13: Sick Leave | F13: Sick Leave | G13: Unplanned | H13: Rejected | I13: =(C13-B13)+1 -> 1 | J13: =B13-B8 -> 40
A14: =VLOOKUP(D14,Transaction!$A$2:$C$477,3,0) -> 42726 | B14: 42887 | C14: 42887 | D14: E12 | E14: Documentation Work | F14: Paid Leave | G14: Unplanned | H14: Rejected | I14: =(C14-B14)+1 -> 1 | J14: =B14-B9 -> 11
A15: =VLOOKUP(D15,Transaction!$A$2:$C$477,3,0) -> 42727 | B15: 42892 | C15: 42893 | D15: E14 | E15: Family function | F15: Casual Leave | G15: Planned | H15: Approved | I15: =(C15-B15)+1 -> 2 | J15: =B15-B10 -> 16
A16: =VLOOKUP(D16,Transaction!$A$2:$C$477,3,0) -> 42728 | B16: 42899 | C16: 42905 | D16: E15 | E16: Family Outing | F16: Casual Leave | G16: Planned | H16: Approved | I16: =(C16-B16)+1 -> 7 | J16: =B16-B11 -> 20
A17: =VLOOKUP(D17,Transaction!$A$2:$C$477,3,0) -> 42767 | B17: 42902 | C17: 42902 | D17: E24 | E17: Sick Leave | F17: Sick Leave | G17: Unplanned | H17: Rejected | I17: =(C17-B17)+1 -> 1 | J17: =B17-B12 -> 19
A18: =VLOOKUP(D18,Transaction!$A$2:$C$477,3,0) -> 42725 | B18: 42948 | C18: 42948 | D18: E7 | E18: Documentation Work | F18: Casual Leave | G18: Planned | H18: Approved | I18: =(C18-B18)+1 -> 1 | J18: =B18-B13 -> 34
A19: =VLOOKUP(D19,Transaction!$A$2:$C$477,3,0) -> 42726 | B19: 42957 | C19: 42957 | D19: E12 | E19: Documentation Work | F19: Casual Leave | G19: Planned | H19: Rejected | I19: =(C19-B19)+1 -> 1 | J19: =B19-B14 -> 70
A20: =VLOOKUP(D20,Transaction!$A$2:$C$477,3,0) -> 42727 | B20: 42960 | C20: 42960 | D20: E14 | E20: Sick Leave | F20: Sick Leave | G20: Unplanned | H20: Approved | I20: =(C20-B20)+1 -> 1 | J20: =B20-B15 -> 68
A21: =VLOOKUP(D21,Transaction!$A$2:$C$477,3,0) -> 42728 | B21: 42962 | C21: 42962 | D21: E15 | E21: Family function | F21: Casual Leave | G21: Planned | H21: Rejected | I21: =(C21-B21)+1 -> 1 | J21: =B21-B16 -> 63
A22: =VLOOKUP(D22,Transaction!$A$2:$C$477,3,0) -> 42767 | B22: 42973 | C22: 42973 | D22: E24 | E22: Sick Leave | F22: Sick Leave | G22: Unplanned | H22: Rejected | I22: =(C22-B22)+1 -> 1 | J22: =B22-B17 -> 71
A23: =VLOOKUP(D23,Transaction!$A$2:$C$477,3,0) -> 42816 | B23: 42975 | C23: 42975 | D23: E307 | E23: Sick Leave | F23: Sick Leave | G23: Unplanned | H23: Rejected | I23: =(C23-B23)+1 -> 1 | J23: =B23-A23 -> 159
A24: =VLOOKUP(D24,Transaction!$A$2:$C$477,3,0) -> 42828 | B24: 42979 | C24: 42981 | D24: E308 | E24: Family Outing | F24: Casual Leave | G24: Planned | H24: Approved | I24: =(C24-B24)+1 -> 3 | J24: =B24-A24 -> 151
A25: =VLOOKUP(D25,Transaction!$A$2:$C$477,3,0) -> 42725 | B25: 42981 | C25: 42985 | D25: E7 | E25: Family Outing | F25: Casual Leave | G25: Unplanned | H25: Rejected | I25: =(C25-B25)+1 -> 5 | J25: =B25-B18 -> 33
A26: =VLOOKUP(D26,Transaction!$A$2:$C$477,3,0) -> 42726 | B26: 42987 | C26: 42987 | D26: E12 | E26: Sick Leave | F26: Sick Leave | G26: Unplanned | H26: Approved | I26: =(C26-B26)+1 -> 1 | J26: =B26-B19 -> 30
A27: =VLOOKUP(D27,Transaction!$A$2:$C$477,3,0) -> 42727 | B27: 42992 | C27: 42996 | D27: E14 | E27: Personal Reason | F27: Leave Without Pay | G27: Unplanned | H27: Approved | I27: =(C27-B27)+1 -> 5 | J27: =B27-B20 -> 32
A28: =VLOOKUP(D28,Transaction!$A$2:$C$477,3,0) -> 42728 | B28: 42995 | C28: 42997 | D28: E15 | E28: Family function | F28: Leave Without Pay | G28: Planned | H28: Approved | I28: =(C28-B28)+1 -> 3 | J28: =B28-B21 -> 33
A29: =VLOOKUP(D29,Transaction!$A$2:$C$477,3,0) -> 42767 | B29: 42999 | C29: 42999 | D29: E24 | E29: Documentation Work | F29: Leave Without Pay | G29: Planned | H29: Rejected | I29: =(C29-B29)+1 -> 1 | J29: =B29-B22 -> 26
A30: =VLOOKUP(D30,Transaction!$A$2:$C$477,3,0) -> 42725 | B30: 43020 | C30: 43022 | D30: E7 | E30: Family Outing | F30: Paid Leave | G30: Planned | H30: Approved | I30: =(C30-B30)+1 -> 3 | J30: =B30-B25 -> 39
A31: =VLOOKUP(D31,Transaction!$A$2:$C$477,3,0) -> 42726 | B31: 43028 | C31: 43028 | D31: E12 | E31: Documentation Work | F31: Casual Leave | G31: Planned | H31: Rejected | I31: =(C31-B31)+1 -> 1 | J31: =B31-B26 -> 41
A32: =VLOOKUP(D32,Transaction!$A$2:$C$477,3,0) -> 42727 | B32: 43040 | C32: 43040 | D32: E14 | E32: Documentation Work | F32: Casual Leave | G32: Planned | H32: Approved | I32: =(C32-B32)+1 -> 1 | J32: =B32-B27 -> 48
A33: =VLOOKUP(D33,Transaction!$A$2:$C$477,3,0) -> 42728 | B33: 43043 | C33: 43043 | D33: E15 | E33: Personal Reason | F33: Leave Without Pay | G33: Unplanned | H33: Rejected | I33: =(C33-B33)+1 -> 1 | J33: =B33-B28 -> 48
A34: =VLOOKUP(D34,Transaction!$A$2:$C$477,3,0) -> 42767 | B34: 43048 | C34: 43051 | D34: E24 | E34: Sick Leave | F34: Sick Leave | G34: Unplanned | H34: Approved | I34: =(C34-B34)+1 -> 4 | J34: =B34-B29 -> 49
A35: =VLOOKUP(D35,Transaction!$A$2:$C$477,3,0) -> 42725 | B35: 43052 | C35: 43053 | D35: E7 | E35: Family Outing | F35: Paid Leave | G35: Planned | H35: Approved | I35: =(C35-B35)+1 -> 2 | J35: =B35-B30 -> 32
A36: =VLOOKUP(D36,Transaction!$A$2:$C$477,3,0) -> 42726 | B36: 43054 | C36: 43054 | D36: E12 | E36: Personal Reason | F36: Leave Without Pay | G36: Unplanned | H36: Rejected | I36: =(C36-B36)+1 -> 1 | J36: =B36-B31 -> 26
A37: =VLOOKUP(D37,Transaction!$A$2:$C$477,3,0) -> 42727 | B37: 43055 | C37: 43059 | D37: E14 | E37: Family function | F37: Casual Leave | G37: Planned | H37: Approved | I37: =(C37-B37)+1 -> 5 | J37: =B37-B32 -> 15
A38: =VLOOKUP(D38,Transaction!$A$2:$C$477,3,0) -> 42728 | B38: 43056 | C38: 43059 | D38: E15 | E38: Family function | F38: Paid Leave | G38: Planned | H38: Approved | I38: =(C38-B38)+1 -> 4 | J38: =B38-B33 -> 13
A39: =VLOOKUP(D39,Transaction!$A$2:$C$477,3,0) -> 42767 | B39: 43060 | C39: 43061 | D39: E24 | E39: Family Outing | F39: Leave Without Pay | G39: Planned | H39: Approved | I39: =(C39-B39)+1 -> 2 | J39: =B39-B34 -> 12
A40: =VLOOKUP(D40,Transaction!$A$2:$C$477,3,0) -> 42725 | B40: 43083 | C40: 43083 | D40: E7 | E40: Family Outing | F40: Paid Leave | G40: Planned | H40: Approved | I40: =(C40-B40)+1 -> 1 | J40: =B40-B35 -> 31
...

Sheet Leave 
A1: Date | B1: EMP ID | C1: Reason for Leave | D1: Type of Leave | E1: Planned/Unplanned | F1: Status | G1: No of Leave
A2: 44287 | B2: E7 | C2: Sick Leave | D2: Sick Leave | E2: Unplanned | F2: Rejected | G2: 1
A3: 44287 | B3: E12 | C3: Family Outing | D3: Casual Leave | E3: Planned | F3: Rejected | G3: 1
A4: 44287 | B4: E14 | C4: Family Outing | D4: Casual Leave | E4: Planned | F4: Rejected | G4: 1
A5: 44287 | B5: E15 | C5: Family Outing | D5: Casual Leave | E5: Planned | F5: Rejected | G5: 1
A6: 44287 | B6: E24 | C6: Sick Leave | D6: Sick Leave | E6: Unplanned | F6: Rejected | G6: 1
A7: 44287 | B7: E27 | C7: Documentation Work | D7: Leave Without Pay | E7: Planned | F7: Rejected | G7: 1
A8: 44287 | B8: E36 | C8: Documentation Work | D8: Leave Without Pay | E8: Planned | F8: Rejected | G8: 1
A9: 44287 | B9: E38 | C9: Family Outing | D9: Paid Leave | E9: Planned | F9: Rejected | G9: 1
A10: 44287 | B10: E53 | C10: Family Outing | D10: Paid Leave | E10: Planned | F10: Rejected | G10: 1
A11: 44287 | B11: E56 | C11: Personal Reason | D11: Leave Without Pay | E11: Planned | F11: Rejected | G11: 1
A12: 44294 | B12: E62 | C12: Family Outing | D12: Casual Leave | E12: Planned | F12: Rejected | G12: 1
A13: 44294 | B13: E63 | C13: Sick Leave | D13: Sick Leave | E13: Unplanned | F13: Rejected | G13: 1
... A547: 44692 | B547: E549 | C547: Documentation Work | D547: Casual Leave | E547: Planned | F547: Approved | G547: 1

Sheet Leave  (3)
A1: Date | B1: EMP ID | C1: Reason for Leave | D1: Type of Leave | E1: Planned/Unplanned | F1: Status | G1: No of Leave | H1: gap
A2: 42830 | B2: E7 | C2: Family function | D2: Casual Leave | E2: Planned | F2: Approved | G2: 1 | H2: =IF(A3="","",A3-A2) -> 44
A3: 42874 | B3: E7 | C3: Sick Leave | D3: Sick Leave | E3: Unplanned | F3: Approved | G3: 1 | H3: =IF(A4="","",A4-A3) -> 40
A4: 42914 | B4: E7 | C4: Sick Leave | D4: Sick Leave | E4: Unplanned | F4: Rejected | G4: 1 | H4: =IF(A5="","",A5-A4) -> 34
A5: 42948 | B5: E7 | C5: Documentation Work | D5: Casual Leave | E5: Planned | F5: Approved | G5: 1 | H5: =IF(A6="","",A6-A5) -> 53
A6: 43001 | B6: E7 | C6: Family Outing | D6: Casual Leave | E6: Unplanned | F6: Rejected | G6: 1 | H6: =IF(A7="","",A7-A6) -> 50
A7: 43051 | B7: E7 | C7: Family Outing | D7: Paid Leave | E7: Planned | F7: Approved | G7: 1 | H7: =IF(A8="","",A8-A7) -> 1
A8: 43052 | B8: E7 | C8: Family Outing | D8: Paid Leave | E8: Planned | F8: Approved | G8: 1 | H8: =IF(A9="","",A9-A8) -> 1
A9: 43053 | B9: E7 | C9: Family Outing | D9: Paid Leave | E9: Planned | F9: Approved | G9: 1 | H9: =IF(A10="","",A10-A9) -> 47
A10: 43100 | B10: E7 | C10: Family function | D10: Casual Leave | E10: Unplanned | F10: Rejected | G10: 1 | H10: =IF(A11="","",A11-A10) -> 12
A11: 43112 | B11: E7 | C11: Sick Leave | D11: Paid Leave | E11: Unplanned | F11: Approved | G11: 1 | H11: =IF(A12="","",A12-A11) -> 83
A12: 43195 | B12: E7 | C12: Family function | D12: Casual Leave | E12: Planned | F12: Approved | G12: 1 | H12: =IF(A13="","",A13-A12) -> 26
A13: 43221 | B13: E7 | C13: Sick Leave | D13: Sick Leave | E13: Unplanned | F13: Rejected | G13: 1 | H13: =IF(A14="","",A14-A13) -> 81
... A41: 44239 | B41: E7 | C41: Sick Leave | D41: Paid Leave | E41: Unplanned | F41: Rejected | G41: 1 | H41: =IF(A42="","",A42-A41)

Sheet Claim
A1: Date | B1: Emp ID | C1: Marrage | D1: Travel | E1: Travel Cost | F1: Food | G1: Food Cost | H1: Special Allowance | I1: Special Allowance Cost | J1: Children Education | K1: Children Education Cost | L1: Internet/Phone Bills | M1: Internet/Phone Bills cost | N1: Medical Reimbursement | O1: Medical Reimbursement cost
A2: 44316 | B2: E7 | C2: Married | D2: Yes | E2: 3687 | F2: Yes | G2: 2555 | H2: Yes | I2: 2296 | J2: Yes | K2: 1881 | L2: No | M2: 0 | N2: Yes | O2: 4493
A3: 44316 | B3: E12 | C3: Married | D3: Yes | E3: 3111 | F3: Yes | G3: 2810 | H3: Yes | I3: 2375 | J3: Yes | K3: 1498 | L3: Yes | M3: 3208 | N3: Yes | O3: 3566
A4: 44316 | B4: E14 | C4: Unmarried | D4: Yes | E4: 3842 | F4: Yes | G4: 2846 | H4: Yes | I4: 2416 | J4: No | K4: 0 | L4: No | M4: 0 | N4: Yes | O4: 4991
A5: 44316 | B5: E15 | C5: Unmarried | D5: Yes | E5: 4332 | F5: Yes | G5: 2977 | H5: Yes | I5: 2276 | J5: No | K5: 0 | L5: No | M5: 0 | N5: Yes | O5: 4423
A6: 44316 | B6: E24 | C6: Unmarried | D6: Yes | E6: 3734 | F6: Yes | G6: 2370 | H6: No | I6: 0 | J6: No | K6: 0 | L6: No | M6: 0 | N6: Yes | O6: 3828
A7: 44316 | B7: E27 | C7: Married | D7: Yes | E7: 3875 | F7: Yes | G7: 2131 | H7: Yes | I7: 2147 | J7: Yes | K7: 1775 | L7: Yes | M7: 3433 | N7: Yes | O7: 5808
A8: 44316 | B8: E36 | C8: Married | D8: Yes | E8: 4726 | F8: Yes | G8: 2540 | H8: Yes | I8: 2527 | J8: Yes | K8: 1803 | L8: No | M8: 0 | N8: Yes | O8: 4548
A9: 44316 | B9: E38 | C9: Married | D9: Yes | E9: 3149 | F9: Yes | G9: 2973 | H9: Yes | I9: 2383 | J9: Yes | K9: 1986 | L9: Yes | M9: 3001 | N9: Yes | O9: 5878
A10: 44316 | B10: E53 | C10: Unmarried | D10: Yes | E10: 3265 | F10: Yes | G10: 2803 | H10: Yes | I10: 2020 | J10: No | K10: 0 | L10: No | M10: 0 | N10: Yes | O10: 3718
A11: 44316 | B11: E56 | C11: Unmarried | D11: Yes | E11: 4976 | F11: Yes | G11: 2583 | H11: No | I11: 0 | J11: No | K11: 0 | L11: No | M11: 0 | N11: Yes | O11: 5028
A12: 44316 | B12: E62 | C12: Unmarried | D12: Yes | E12: 3599 | F12: Yes | G12: 2197 | H12: No | I12: 0 | J12: No | K12: 0 | L12: No | M12: 0 | N12: Yes | O12: 3714
A13: 44316 | B13: E63 | C13: Married | D13: Yes | E13: 3895 | F13: Yes | G13: 2632 | H13: No | I13: 0 | J13: Yes | K13: 1812 | L13: No | M13: 0 | N13: Yes | O13: 4098
